Workbook
Name _top1: [1]PID_MS1!#REF!
Name last1: [1]PID_MS1!#REF!

Sheet P0000-P3FFF
A1: Type | B1: Abs# | C1: Number | D1: 2 byte DTC -OR- 3 byte DTC using DTC Format Identifier 0x00 | E1: Location | F1: Note | G1: To convert to format 0x04, use the following DTC #: | H1: 3 byte DTC using DTC Format Identifier 0x04 | I1: FTB (hex) | J1: FTB Description
A2: Table | C2: P00 | D2: Table P00 | G2: ---- | H2: =D2 -> Table P00 | I2: ----
C3: P0000 | D3: ISO/SAE Reserved | G3: ISO/SAE Reserved | H3: ISO/SAE Reserved | I3: ISO/SAE Reserved
C4: P0001 | D4: Fuel Volume Regulator "A" Control Circuit/Open | G4: P0001 | H4: Fuel Volume Regulator "A" Control | I4: 13 | J4: =VLOOKUP(I4,FTB.Sub.Types!$A$2:$B$258,2) -> Circuit Open
C5: P0002 | D5: Fuel Volume Regulator "A" Control Circuit Performance | G5: P0001 | H5: ISO/SAE Reserved - Previously Defined for 2-Byte DTCs | I5: 92 | J5: =VLOOKUP(I5,FTB.Sub.Types!$A$2:$B$258,2) -> Performance or Incorrect Operation
C6: P0003 | D6: Fuel Volume Regulator "A" Control Circuit Low | G6: P0001 | H6: ISO/SAE Reserved - Previously Defined for 2-Byte DTCs | I6: 11 | J6: =VLOOKUP(I6,FTB.Sub.Types!$A$2:$B$258,2) -> Circuit Short To Ground
C7: P0004 | D7: Fuel Volume Regulator "A" Control Circuit High | G7: P0001 | H7: ISO/SAE Reserved - Previously Defined for 2-Byte DTCs | I7: 12 | J7: =VLOOKUP(I7,FTB.Sub.Types!$A$2:$B$258,2) -> Circuit Short To Battery
C8: P0005 | D8: Fuel Shutoff Valve "A" Control Circuit/Open | G8: P0005 | H8: Fuel Shutoff Valve "A" Control | I8: 13 | J8: =VLOOKUP(I8,FTB.Sub.Types!$A$2:$B$258,2) -> Circuit Open
C9: P0006 | D9: Fuel Shutoff Valve "A" Control Circuit Low | G9: P0005 | H9: ISO/SAE Reserved - Previously Defined for 2-Byte DTCs | I9: 11 | J9: =VLOOKUP(I9,FTB.Sub.Types!$A$2:$B$258,2) -> Circuit Short To Ground
C10: P0007 | D10: Fuel Shutoff Valve "A" Control Circuit High | G10: P0005 | H10: ISO/SAE Reserved - Previously Defined for 2-Byte DTCs | I10: 12 | J10: =VLOOKUP(I10,FTB.Sub.Types!$A$2:$B$258,2) -> Circuit Short To Battery
C11: P0008 | D11: Engine Position System Performance Bank 1 | G11: P0008 | H11: Engine Position System Performance Bank 1 | I11: 0 | J11: =VLOOKUP(I11,FTB.Sub.Types!$A$2:$B$258,2) -> No Sub Type Information
C12: P0009 | D12: Engine Position System Performance Bank 2 | G12: P0009 | H12: Engine Position System Performance Bank 2 | I12: 0 | J12: =VLOOKUP(I12,FTB.Sub.Types!$A$2:$B$258,2) -> No Sub Type Information
C13: P000A | D13: "A" Camshaft Position Slow Response Bank 1 | F13: a | G13: P000A | H13: "A" Camshaft Position Bank 1 | I13: 7C | J13: =VLOOKUP(I13,FTB.Sub.Types!$A$2:$B$258,2) -> Slow Response
C14: P000B | D14: "B" Camshaft Position Slow Response Bank 1 | F14: b | G14: P000B | H14: "B" Camshaft Position Bank 1 | I14: 7C | J14: =VLOOKUP(I14,FTB.Sub.Types!$A$2:$B$258,2) -> Slow Response
C15: P000C | D15: "A" Camshaft Position Slow Response Bank 2 | F15: a | G15: P000C | H15: "A" Camshaft Position Bank 2 | I15: 7C | J15: =VLOOKUP(I15,FTB.Sub.Types!$A$2:$B$258,2) -> Slow Response
C16: P000D | D16: "B" Camshaft Position Slow Response Bank 2 | F16: b | G16: P000D | H16: "B" Camshaft Position Bank 2 | I16: 7C | J16: =VLOOKUP(I16,FTB.Sub.Types!$A$2:$B$258,2) -> Slow Response
C17: P000E | D17: Fuel Volume Regulator Control Exceeded Learning Limit | G17: P0001 | H17: ISO/SAE Reserved - Previously Defined for 2-Byte DTCs | I17: 99 | J17: =VLOOKUP(I17,FTB.Sub.Types!$A$2:$B$258,2) -> Exceeded Learning Limit
C18: P000F | D18: Fuel System Over Pressure Relief Valve Activated | G18: P000F | H18: Fuel System Over Pressure Relief Valve Activated | I18: 0 | J18: =VLOOKUP(I18,FTB.Sub.Types!$A$2:$B$258,2) -> No Sub Type Information
C19: P0010 | D19: "A" Camshaft Position Actuator "A" Control Circuit/Open Bank 1 | F19: a | G19: P0010 | H19: "A" Camshaft Position Actuator "A" Control | I19: 13 | J19: =VLOOKUP(I19,FTB.Sub.Types!$A$2:$B$258,2) -> Circuit Open
C20: P0011 | D20: "A" Camshaft Position - Timing Over-Advanced or System Performance Bank 1 | F20: a | G20: P0011 | H20: "A" Camshaft Position - Timing Over-Advanced or System Performance Bank 1 | I20: 0 | J20: =VLOOKUP(I20,FTB.Sub.Types!$A$2:$B$258,2) -> No Sub Type Information
C21: P0012 | D21: "A" Camshaft Position - Timing Over-Retarded Bank 1 | F21: a | G21: P0012 | H21: "A" Camshaft Position - Timing Over-Retarded Bank 1 | I21: 0 | J21: =VLOOKUP(I21,FTB.Sub.Types!$A$2:$B$258,2) -> No Sub Type Information
C22: P0013 | D22: "B" Camshaft Position Actuator "A" Control Circuit/Open Bank 1 | F22: b | G22: P0013 | H22: "B" Camshaft Position Actuator "A" Control | I22: 13 | J22: =VLOOKUP(I22,FTB.Sub.Types!$A$2:$B$258,2) -> Circuit Open
C23: P0014 | D23: "B" Camshaft Position - Timing Over-Advanced or System Performance Bank 1 | F23: b | G23: P0014 | H23: "B" Camshaft Position - Timing Over-Advanced or System Performance Bank 1 | I23: 0 | J23: =VLOOKUP(I23,FTB.Sub.Types!$A$2:$B$258,2) -> No Sub Type Information
C24: P0015 | D24: "B" Camshaft Position - Timing Over-Retarded Bank 1 | F24: b | G24: P0015 | H24: "B" Camshaft Position - Timing Over-Retarded Bank 1 | I24: 0 | J24: =VLOOKUP(I24,FTB.Sub.Types!$A$2:$B$258,2) -> No Sub Type Information
C25: P0016 | D25: Crankshaft Position - Camshaft Position Correlation Bank 1 Sensor A | G25: P0016 | H25: Crankshaft Position - Camshaft Position Correlation Bank 1 Sensor A | I25: 0 | J25: =VLOOKUP(I25,FTB.Sub.Types!$A$2:$B$258,2) -> No Sub Type Information
C26: P0017 | D26: Crankshaft Position - Camshaft Position Correlation Bank 1 Sensor B | G26: P0017 | H26: Crankshaft Position - Camshaft Position Correlation Bank 1 Sensor B | I26: 0 | J26: =VLOOKUP(I26,FTB.Sub.Types!$A$2:$B$258,2) -> No Sub Type Information
C27: P0018 | D27: Crankshaft Position - Camshaft Position Correlation Bank 2 Sensor A | G27: P0018 | H27: Crankshaft Position - Camshaft Position Correlation Bank 2 Sensor A | I27: 0 | J27: =VLOOKUP(I27,FTB.Sub.Types!$A$2:$B$258,2) -> No Sub Type Information
C28: P0019 | D28: Crankshaft Position - Camshaft Position Correlation Bank 2 Sensor B | G28: P0019 | H28: Crankshaft Position - Camshaft Position Correlation Bank 2 Sensor B | I28: 0 | J28: =VLOOKUP(I28,FTB.Sub.Types!$A$2:$B$258,2) -> No Sub Type Information
C29: P001A | D29: "A" Camshaft Profile Actuator "A" Control Circuit/Open Bank 1 | F29: a | G29: P001A | H29: "A" Camshaft Profile Actuator "A" Control | I29: 13 | J29: =VLOOKUP(I29,FTB.Sub.Types!$A$2:$B$258,2) -> Circuit Open
C30: P001B | D30: "A" Camshaft Profile Actuator "A" Control Circuit Low Bank 1 | F30: a | G30: P001A | H30: ISO/SAE Reserved - Previously Defined for 2-Byte DTCs | I30: 11 | J30: =VLOOKUP(I30,FTB.Sub.Types!$A$2:$B$258,2) -> Circuit Short To Ground
C31: P001C | D31: "A" Camshaft Profile Actuator "A" Control Circuit High Bank 1 | F31: a | G31: P001A | H31: ISO/SAE Reserved - Previously Defined for 2-Byte DTCs | I31: 12 | J31: =VLOOKUP(I31,FTB.Sub.Types!$A$2:$B$258,2) -> Circuit Short To Battery
C32: P001D | D32: "A" Camshaft Profile Actuator "A" Control Circuit/Open Bank 2 | F32: a | G32: P001D | H32: "A" Camshaft Profile Actuator "A" Control Bank 2 | I32: 13 | J32: =VLOOKUP(I32,FTB.Sub.Types!$A$2:$B$258,2) -> Circuit Open
C33: P001E | D33: "A" Camshaft Profile Actuator "A" Control Circuit Low Bank 2 | F33: a | G33: P001D | H33: ISO/SAE Reserved - Previously Defined for 2-Byte DTCs | I33: 11 | J33: =VLOOKUP(I33,FTB.Sub.Types!$A$2:$B$258,2) -> Circuit Short To Ground
C34: P001F | D34: "A" Camshaft Profile Actuator "A" Control Circuit High Bank 2 | F34: a | G34: P001D | H34: ISO/SAE Reserved - Previously Defined for 2-Byte DTCs | I34: 12 | J34: =VLOOKUP(I34,FTB.Sub.Types!$A$2:$B$258,2) -> Circuit Short To Battery
C35: P0020 | D35: "A" Camshaft Position Actuator "A" Control Circuit/Open Bank 2 | F35: a | G35: P001D | H35: ISO/SAE Reserved - Previously Defined for 2-Byte DTCs | I35: 13 | J35: =VLOOKUP(I35,FTB.Sub.Types!$A$2:$B$258,2) -> Circuit Open
C36: P0021 | D36: "A" Camshaft Position - Timing Over-Advanced or System Performance Bank 2 | F36: a | G36: P0021 | H36: "A" Camshaft Position - Timing Over-Advanced or System Performance Bank 2 | I36: 0 | J36: =VLOOKUP(I36,FTB.Sub.Types!$A$2:$B$258,2) -> No Sub Type Information
C37: P0022 | D37: "A" Camshaft Position - Timing Over-Retarded Bank 2 | F37: a | G37: P0022 | H37: "A" Camshaft Position - Timing Over-Retarded Bank 2 | I37: 0 | J37: =VLOOKUP(I37,FTB.Sub.Types!$A$2:$B$258,2) -> No Sub Type Information
C38: P0023 | D38: "B" Camshaft Position Actuator "A" Control Circuit/Open Bank 2 | F38: b | G38: P0023 | H38: "B" Camshaft Position Actuator "A" Control Bank 2 | I38: 13 | J38: =VLOOKUP(I38,FTB.Sub.Types!$A$2:$B$258,2) -> Circuit Open
C39: P0024 | D39: "B" Camshaft Position - Timing Over-Advanced or System Performance Bank 2 | F39: b | G39: P0024 | H39: "B" Camshaft Position - Timing Over-Advanced or System Performance Bank 2 | I39: 0 | J39: =VLOOKUP(I39,FTB.Sub.Types!$A$2:$B$258,2) -> No Sub Type Information
C40: P0025 | D40: "B" Camshaft Position - Timing Over-Retarded Bank 2 | F40: b | G40: P0025 | H40: "B" Camshaft Position - Timing Over-Retarded Bank 2 | I40: 0 | J40: =VLOOKUP(I40,FTB.Sub.Types!$A$2:$B$258,2) -> No Sub Type Information
...

Sheet B0000-B3FFF
A1: Type | B1: Abs# | C1: Number | D1: 3 byte DTC using DTC Format Identifier 0x00 -OR- 3 byte DTC using DTC Format Identifier 0x04 | E1: Location | F1: Note | G1: Comment | H1: ="Reserved"&" "&COUNTIF(D:D, "ISO/SAE Reserved") -> Reserved 4070
A2: Table | C2: B00 | D2: Table B00
B3: 0 | C3: B0000 | D3: ISO/SAE Reserved
B4: 1 | C4: B0001 | D4: Driver Frontal Stage 1 Deployment Control
B5: 2 | C5: B0002 | D5: Driver Frontal Stage 2 Deployment Control
B6: 3 | C6: B0003 | D6: Driver Frontal Stage 3 Deployment Control
B7: 4 | C7: B0004 | D7: Driver Knee Bolster Deployment Control
B8: 5 | C8: B0005 | D8: Collapsible Steering Column Deployment Control
B9: 6 | C9: B0006 | D9: ISO/SAE Reserved
B10: 7 | C10: B0007 | D10: ISO/SAE Reserved
B11: 8 | C11: B0008 | D11: ISO/SAE Reserved
B12: 9 | C12: B0009 | D12: ISO/SAE Reserved
B13: A | C13: B000A | D13: ISO/SAE Reserved
B14: B | C14: B000B | D14: ISO/SAE Reserved
... B4098: FFF | C4098: B0FFF | D4098: ISO/SAE Reserved
A4099: Table | C4099: B1XXX | D4099: Table B1XXX Manufacturer Controlled DTC
B4100: 1000 | C4100: B1000 | D4100: Manufacturer Controlled DTC
A4101: Table | C4101: B2XXX | D4101: Table B2XXX Manufacturer Controlled DTC
B4102: 2000 | C4102: B2000 | D4102: Manufacturer Controlled DTC
A4103: Table | C4103: B3000-B3999 | D4103: Table B3000-B3999 ISO/SAE Reserved
B4104: B3000 | C4104: B3000 | D4104: B3000-B3999 ISO/SAE Reserved
A4105: Table | C4105: B3A00-B3AFF | D4105: Table ISO/SAE Industry Standard DTC
B4106: 3A00 | C4106: B3A00 | D4106: A/C Refrigerant Distribution Valve Actuator "C" Stuck/Open
C4107: B3A01 | D4107: A/C Refrigerant Distribution Valve Actuator "C" Control Circuit/Open
C4108: B3A02 | D4108: A/C Refrigerant Distribution Valve Actuator "C" Control Circuit Low
C4109: B3A03 | D4109: A/C Refrigerant Distribution Valve Actuator "C" Control Circuit High
C4110: B3A04 | D4110: A/C Refrigerant Distribution Valve "C" Control Circuit Driver Current/Temperature Too High
C4111: B3A05 | D4111: A/C Refrigerant Distribution Valve Actuator "D" Stuck/Open
C4112: B3A06 | D4112: A/C Refrigerant Distribution Valve Actuator "D" Control Circuit/Open
C4113: B3A07 | D4113: A/C Refrigerant Distribution Valve Actuator "D" Control Circuit Low
C4114: B3A08 | D4114: A/C Refrigerant Distribution Valve Actuator "D" Control Circuit High
C4115: B3A09 | D4115: A/C Refrigerant Distribution Valve "D" Control Circuit Driver Current/Temperature Too High
C4116: B3A0A | D4116: A/C Refrigerant Expansion Valve Actuator Stuck/Open
C4117: B3A0B | D4117: A/C Refrigerant Expansion Valve Actuator Control Circuit/Open
C4118: B3A0C | D4118: A/C Refrigerant Expansion Valve Actuator Control Circuit Low
... C4361: B3AFF | D4361: Table B3B00-B3FFF ISO/SAE Reserved
A4362: Table | C4362: B3B00-B3FFF | D4362: B3B00-B3FFF ISO/SAE Reserved
B4363: 3B00 | C4363: B3B00

Sheet C0000-C3FFF
A1: Type | B1: Abs# | C1: Number | D1: 3 byte DTC using DTC Format Identifier 0x00 -OR- 3 byte DTC using DTC Format Identifier 0x04 | E1: Location | F1: Note | G1: Comment | H1: ="Reserved"&" "&COUNTIF(D:D, "ISO/SAE Reserved") -> Reserved 3619
A2: Table | C2: C0X | D2: Table C0X
B3: 0 | C3: C0000 | D3: ISO/SAE Reserved
B4: 1 | C4: C0001 | D4: TCS Control Channel "A" Valve 1
B5: 2 | C5: C0002 | D5: TCS Control Channel "A" Valve 2
B6: 3 | C6: C0003 | D6: TCS Control Channel "B" Valve 1
B7: 4 | C7: C0004 | D7: TCS Control Channel "B" Valve 2
B8: 5 | C8: C0005 | D8: ISO/SAE Reserved
B9: 6 | C9: C0006 | D9: ISO/SAE Reserved
B10: 7 | C10: C0007 | D10: ISO/SAE Reserved
B11: 8 | C11: C0008 | D11: ISO/SAE Reserved
B12: 9 | C12: C0009 | D12: ISO/SAE Reserved
B13: A | C13: C000A | D13: ISO/SAE Reserved
B14: B | C14: C000B | D14: ISO/SAE Reserved
... B4098: FFF | C4098: C0FFF | D4098: ISO/SAE Reserved
A4099: Table | C4099: C1XXX | D4099: Table C1XXX Manufacturer Controlled DTC
B4100: 1000 | C4100: C1000 | D4100: Manufacturer Controlled DTC
A4101: Table | C4101: C2XXX | D4101: Table C2XXX Manufacturer Controlled DTC
B4102: 2000 | C4102: C2000 | D4102: Manufacturer Controlled DTC
A4103: Table | C4103: C3XXX | D4103: Table C3XXX ISO/SAE Reserved
B4104: 3000 | C4104: C3000 | D4104: ISO/SAE Reserved

Sheet U0000-U3FFF
A1: Type | B1: Abs# | C1: Number | D1: 2 byte DTC -OR- 3 byte DTC using DTC Format Identifier 0x00 | E1: Location | F1: Note | G1: To convert to format 0x04, use the following DTC #: | H1: 3 byte DTC using DTC Format Identifier 0x04 | I1: FTB (hex) | J1: FTB Description
A2: Table | C2: U00 | D2: Table U00 | G2: ---- | H2: =D2 -> Table U00 | I2: ---- | J2: ----
B3: 0 | C3: U0000 | D3: ISO/SAE Reserved | G3: ISO/SAE Reserved | H3: ISO/SAE Reserved | I3: ISO/SAE Reserved | J3: ISO/SAE Reserved
B4: 1 | C4: U0001 | D4: High Speed CAN Communication Bus | G4: U0001 | H4: High Speed CAN Communication Bus | I4: 0 | J4: =VLOOKUP(I4,FTB.Sub.Types!$A$2:$B$257,2) -> No Sub Type Information
B5: 2 | C5: U0002 | D5: High Speed CAN Communication Bus Performance | G5: U0001 | H5: SAE Reserved - Previously Defined for 2-Byte DTCs | I5: 92 | J5: =VLOOKUP(I5,FTB.Sub.Types!$A$2:$B$257,2) -> Performance or Incorrect Operation
B6: 3 | C6: U0003 | D6: High Speed CAN Communication Bus (+) Open | G6: U0003 | H6: High Speed CAN Communication Bus (+) | I6: 13 | J6: =VLOOKUP(I6,FTB.Sub.Types!$A$2:$B$258,2) -> Circuit Open
B7: 4 | C7: U0004 | D7: High Speed CAN Communication Bus (+) Low | G7: U0003 | H7: SAE Reserved - Previously Defined for 2-Byte DTCs | I7: 11 | J7: =VLOOKUP(I7,FTB.Sub.Types!$A$2:$B$258,2) -> Circuit Short To Ground
B8: 5 | C8: U0005 | D8: High Speed CAN Communication Bus (+) High | G8: U0003 | H8: SAE Reserved - Previously Defined for 2-Byte DTCs | I8: 12 | J8: =VLOOKUP(I8,FTB.Sub.Types!$A$2:$B$258,2) -> Circuit Short To Battery
B9: 6 | C9: U0006 | D9: High Speed CAN Communication Bus (-) Open | G9: U0006 | H9: High Speed CAN Communication Bus (–) | I9: 13 | J9: =VLOOKUP(I9,FTB.Sub.Types!$A$2:$B$258,2) -> Circuit Open
B10: 7 | C10: U0007 | D10: High Speed CAN Communication Bus (-) Low | G10: U0006 | H10: SAE Reserved - Previously Defined for 2-Byte DTCs | I10: 11 | J10: =VLOOKUP(I10,FTB.Sub.Types!$A$2:$B$258,2) -> Circuit Short To Ground
B11: 8 | C11: U0008 | D11: High Speed CAN Communication Bus (-) High | G11: U0006 | H11: SAE Reserved - Previously Defined for 2-Byte DTCs | I11: 12 | J11: =VLOOKUP(I11,FTB.Sub.Types!$A$2:$B$258,2) -> Circuit Short To Battery
B12: 9 | C12: U0009 | D12: High Speed CAN Communication Bus (-) shorted to Bus (+) | G12: U0001 | H12: SAE Reserved - Previously Defined for 2-Byte DTCs | I12: 2B | J12: =VLOOKUP(I12,FTB.Sub.Types!$A$2:$B$258,2) -> Signal Cross Coupled
B13: A | C13: U000A | D13: ISO/SAE Reserved | G13: ISO/SAE Reserved | H13: ISO/SAE Reserved | I13: ISO/SAE Reserved | J13: =VLOOKUP(I13,FTB.Sub.Types!$A$2:$B$258,2) -> ISO/SAE Reserved
B14: B | C14: U000B | D14: ISO/SAE Reserved | G14: ISO/SAE Reserved | H14: ISO/SAE Reserved | I14: ISO/SAE Reserved | J14: =VLOOKUP(I14,FTB.Sub.Types!$A$2:$B$258,2) -> ISO/SAE Reserved
B15: C | C15: U000C | D15: ISO/SAE Reserved | G15: ISO/SAE Reserved | H15: ISO/SAE Reserved | I15: ISO/SAE Reserved | J15: =VLOOKUP(I15,FTB.Sub.Types!$A$2:$B$258,2) -> ISO/SAE Reserved
B16: D | C16: U000D | D16: ISO/SAE Reserved | G16: ISO/SAE Reserved | H16: ISO/SAE Reserved | I16: ISO/SAE Reserved | J16: =VLOOKUP(I16,FTB.Sub.Types!$A$2:$B$258,2) -> ISO/SAE Reserved
B17: E | C17: U000E | D17: ISO/SAE Reserved | G17: ISO/SAE Reserved | H17: ISO/SAE Reserved | I17: ISO/SAE Reserved | J17: =VLOOKUP(I17,FTB.Sub.Types!$A$2:$B$258,2) -> ISO/SAE Reserved
B18: F | C18: U000F | D18: ISO/SAE Reserved | G18: ISO/SAE Reserved | H18: ISO/SAE Reserved | I18: ISO/SAE Reserved | J18: =VLOOKUP(I18,FTB.Sub.Types!$A$2:$B$258,2) -> ISO/SAE Reserved
B19: 10 | C19: U0010 | D19: Medium Speed CAN Communication Bus | G19: U0010 | H19: Medium Speed CAN Communication Bus | I19: 0 | J19: =VLOOKUP(I19,FTB.Sub.Types!$A$2:$B$258,2) -> No Sub Type Information
B20: 11 | C20: U0011 | D20: Medium Speed CAN Communication Bus Performance | G20: U0010 | H20: SAE Reserved - Previously Defined for 2-Byte DTCs | I20: 92 | J20: =VLOOKUP(I20,FTB.Sub.Types!$A$2:$B$258,2) -> Performance or Incorrect Operation
B21: 12 | C21: U0012 | D21: Medium Speed CAN Communication Bus (+) Open | G21: U0012 | H21: Medium Speed CAN Communication Bus (+) | I21: 13 | J21: =VLOOKUP(I21,FTB.Sub.Types!$A$2:$B$258,2) -> Circuit Open
B22: 13 | C22: U0013 | D22: Medium Speed CAN Communication Bus (+) Low | G22: U0012 | H22: SAE Reserved - Previously Defined for 2-Byte DTCs | I22: 11 | J22: =VLOOKUP(I22,FTB.Sub.Types!$A$2:$B$258,2) -> Circuit Short To Ground
B23: 14 | C23: U0014 | D23: Medium Speed CAN Communication Bus (+) High | G23: U0012 | H23: SAE Reserved - Previously Defined for 2-Byte DTCs | I23: 12 | J23: =VLOOKUP(I23,FTB.Sub.Types!$A$2:$B$258,2) -> Circuit Short To Battery
B24: 15 | C24: U0015 | D24: Medium Speed CAN Communication Bus (-) Open | G24: U0015 | H24: Medium Speed CAN Communication Bus (–) | I24: 13 | J24: =VLOOKUP(I24,FTB.Sub.Types!$A$2:$B$258,2) -> Circuit Open
B25: 16 | C25: U0016 | D25: Medium Speed CAN Communication Bus (-) Low | G25: U0015 | H25: SAE Reserved - Previously Defined for 2-Byte DTCs | I25: 11 | J25: =VLOOKUP(I25,FTB.Sub.Types!$A$2:$B$258,2) -> Circuit Short To Ground
B26: 17 | C26: U0017 | D26: Medium Speed CAN Communication Bus (-) High | G26: U0015 | H26: SAE Reserved - Previously Defined for 2-Byte DTCs | I26: 12 | J26: =VLOOKUP(I26,FTB.Sub.Types!$A$2:$B$258,2) -> Circuit Short To Battery
B27: 18 | C27: U0018 | D27: Medium Speed CAN Communication Bus (-) shorted to Bus (+) | G27: U0010 | H27: SAE Reserved - Previously Defined for 2-Byte DTCs | I27: 2B | J27: =VLOOKUP(I27,FTB.Sub.Types!$A$2:$B$258,2) -> Signal Cross Coupled
B28: 19 | C28: U0019 | D28: Low Speed CAN Communication Bus | G28: U0019 | H28: Low Speed CAN Communication Bus | I28: 0 | J28: =VLOOKUP(I28,FTB.Sub.Types!$A$2:$B$258,2) -> No Sub Type Information
B29: 1A | C29: U001A | D29: ISO/SAE Reserved | G29: ISO/SAE Reserved | H29: ISO/SAE Reserved | I29: ISO/SAE Reserved | J29: =VLOOKUP(I29,FTB.Sub.Types!$A$2:$B$258,2) -> ISO/SAE Reserved
B30: 1B | C30: U001B | D30: ISO/SAE Reserved | G30: ISO/SAE Reserved | H30: ISO/SAE Reserved | I30: ISO/SAE Reserved | J30: =VLOOKUP(I30,FTB.Sub.Types!$A$2:$B$258,2) -> ISO/SAE Reserved
B31: 1C | C31: U001C | D31: ISO/SAE Reserved | G31: ISO/SAE Reserved | H31: ISO/SAE Reserved | I31: ISO/SAE Reserved | J31: =VLOOKUP(I31,FTB.Sub.Types!$A$2:$B$258,2) -> ISO/SAE Reserved
B32: 1D | C32: U001D | D32: ISO/SAE Reserved | G32: ISO/SAE Reserved | H32: ISO/SAE Reserved | I32: ISO/SAE Reserved | J32: =VLOOKUP(I32,FTB.Sub.Types!$A$2:$B$258,2) -> ISO/SAE Reserved
B33: 1E | C33: U001E | D33: ISO/SAE Reserved | G33: ISO/SAE Reserved | H33: ISO/SAE Reserved | I33: ISO/SAE Reserved | J33: =VLOOKUP(I33,FTB.Sub.Types!$A$2:$B$258,2) -> ISO/SAE Reserved
B34: 1F | C34: U001F | D34: ISO/SAE Reserved | G34: ISO/SAE Reserved | H34: ISO/SAE Reserved | I34: ISO/SAE Reserved | J34: =VLOOKUP(I34,FTB.Sub.Types!$A$2:$B$258,2) -> ISO/SAE Reserved
B35: 20 | C35: U0020 | D35: Low Speed CAN Communication Bus Performance | G35: U0019 | H35: SAE Reserved - Previously Defined for 2-Byte DTCs | I35: 92 | J35: =VLOOKUP(I35,FTB.Sub.Types!$A$2:$B$258,2) -> Performance or Incorrect Operation
B36: 21 | C36: U0021 | D36: Low Speed CAN Communication Bus (+) Open | G36: U0021 | H36: Low Speed CAN Communication Bus (+) | I36: 13 | J36: =VLOOKUP(I36,FTB.Sub.Types!$A$2:$B$258,2) -> Circuit Open
B37: 22 | C37: U0022 | D37: Low Speed CAN Communication Bus (+) Low | G37: U0021 | H37: SAE Reserved - Previously Defined for 2-Byte DTCs | I37: 11 | J37: =VLOOKUP(I37,FTB.Sub.Types!$A$2:$B$258,2) -> Circuit Short To Ground
B38: 23 | C38: U0023 | D38: Low Speed CAN Communication Bus (+) High | G38: U0021 | H38: SAE Reserved - Previously Defined for 2-Byte DTCs | I38: 12 | J38: =VLOOKUP(I38,FTB.Sub.Types!$A$2:$B$258,2) -> Circuit Short To Battery
B39: 24 | C39: U0024 | D39: Low Speed CAN Communication Bus (-) Open | G39: U0024 | H39: Low Speed CAN Communication Bus (–) | I39: 13 | J39: =VLOOKUP(I39,FTB.Sub.Types!$A$2:$B$258,2) -> Circuit Open
B40: 25 | C40: U0025 | D40: Low Speed CAN Communication Bus (-) Low | G40: U0024 | H40: SAE Reserved - Previously Defined for 2-Byte DTCs | I40: 11 | J40: =VLOOKUP(I40,FTB.Sub.Types!$A$2:$B$258,2) -> Circuit Short To Ground
...

Sheet Notes
A1: Note | B1: Note Text
A2: 1 | B2: For DTCs P0540 - P0543 also see P2604 - P2609
A3: 2 | B3: For DTCs P0578 - P0581 also see P0564
A4: 3 | B4: DTCs P2141 - P2142 should be used with P0487 - P0488
A5: 4 | B5: P2231 - P2236, This diagnostic is for the sensors (both wide band and switching) that have a PWM controlled heater. If the heater shorts to the signal circuit, the control module can determine this since the signal circuit will be shorted high at the same frequency that the heaters are operating at.
A6: 5 | B6: P2237 - P2256, These are the diagnostics for the primary circuits of the wide band oxygen sensors.
A7: 6 | B7: For DTCs P2505 - P2509 also see P0685
A8: 7 | B8: For DTCs P2604 - P2609 also see P0540 - P0543
A9: 8 | B9: For DTCs P2088 - P2095 also see P0010 - P0023
A10: 9 | B10: For Throttle Actuator Control DTCs also see P0638 - P0639
A11: a | B11: The "A" camshaft shall be either the "intake," "left," or "front" camshaft. Left/Right and Front/Rear are determined as if viewed from the driver's seating position. Bank 1 contains cylinder number one, Bank 2 is the opposite bank. Manufacturers must use alternative definitions for “A” and “B” consistently across their entire product line.
A12: b | B12: The "B" camshaft shall be either the "exhaust," "right," or "rear" camshaft. Left/Right and Front/Rear are determined as if viewed from the driver's seating position. Bank 1 contains cylinder number one, Bank 2 is the opposite bank. Manufacturers must use alternative definitions for “A” and “B” consistently across their entire product line.
A13: c | B13: DTC Application note for Intake Manifold Tuning Valves and Intake Manifold Runner controls: Active controls are used to modify or control airflow within the engine air intake system. These controls may be used to enhance or modify in-cylinder airflow motion (charge motion), modify the airflow dynamics (manifold tuning) within the intake manifold or both. Devices that control charge motion are commonly called Intake Manifold Runner Control, Swirl Control Valve, and Charge Motion Control Valve. The ISO/SAE recommended term for any device that controls charge motion is Intake Manifold Runner Control (IMRC). Devices that control manifold dynamics or manifold tuning are commonly called Intake Manifold Tuning Valve, Long/Short Runner Control and Intake Manifold Communication Control. The SAE recommended term for any device that controls manifold tuning is Intake Manifold Tuning (IMT) Valve.
A14: d | B14: Use P2177 - P2180 for fuel systems with multiple load ranges.
A15: e | B15: The "A" rocker arm actuator shall be either the "intake," "left," or "front" rocker arm actuator. Left/Right and Front/Rear are determined as if viewed from the driver's seating position. Bank 1 contains cylinder number one, Bank 2 is the opposite bank. Where only one rocker arm actuator is used for both conditions "A" and "B", use the DTCs for "A".
A16: f | B16: The "B" rocker arm actuator shall be either the "exhaust," "right," or "rear" rocker arm actuator. Left/Right and Front/Rear are determined as if viewed from the driver's seating position. Bank 1 contains cylinder number one, Bank 2 is the opposite bank. Where only one rocker arm actuator is used for both conditions "A" and "B", use the DTCs for "A".
A17: g | B17: Use P2BA6-P2BAF for NOx Control Exceedance Diagnostic Requirements (Inducement)
A18: h | B18: Typically used with a clutched Fan
A19: i | B19: Throttle/Pedal Position Sensor PIDs The following DTCs are generally assigned to throttle position: P0120 Throttle/Pedal Position Sensor "A" Circuit (J1979 PID $11 Absolute Throttle Position) P0220 Throttle/Pedal Position Sensor/Switch "B" Circuit (J1979 PID $47 Absolute Throttle Position B) P0225 Throttle/Pedal Position Sensor/Switch "C" Circuit (J1979 PID $48 Absolute Throttle Position C) P212A Throttle/Pedal Position Sensor/Switch "G" Circuit (J1979 PID $8D Absolute Throttle Position G) Early implementations used three sensors for redundancy. Later implementations went to two sensors with opposing slopes. “G” was added for a dual throttle body application where A and B were used for throttle body A and C and G were used for throttle body B. The following DTCs are generally assigned to pedal position. Early implementations used three sensors for redundancy. Later implementations went to two sensors with opposing slopes. P2120 Throttle/Pedal Position Sensor/Switch "D" Circuit (J1979 PID $49 Accelerator Pedal Position D) P2125 Throttle/Pedal Position Sensor/Switch "E" Circuit (J1979 PID $4A Accelerator Pedal Position E) P2130 Throttle/Pedal Position Sensor/Switch "F" Circuit (J1979 PID $4B Accelerator Pedal Position F)
A20: j | B20: Smart Device The OBD-II regulations (1968.2) now address requirements for smart devices. “Diagnostic or emission critical” electronic powertrain control unit refers to the engine and transmission control unit(s). For the 2005 and subsequent model years, it also includes any other on-board electronic powertrain control unit that: (1) has primary control over any of the monitors required by sections (e)(1) through (e)(14), (e)(16), (f)(1) through (f)(14), and (f)(16), but does not include circuit or out-of-range fault monitors required by sections (e)(7.2.1)(B), (e)(7.2.2)(B), (e)(7.2.2)(D), (e)(7.2.3)(B), (e)(10.2.2)(A), (f)(5.2.1)(A)(ii), (f)(5.2.1)(B)(ii), (f)(5.2.2)(B), (f)(5.2.4)(B), and (f)(11.2.2)(A); or, (2) except for anti-lock brake system (ABS) control units or stability/traction control units, has primary control over any rationality fault diagnostics or functional check for more than four input components or more than two output components required to be monitored by sections (e)(15.0) and (f)(15); or (3) for 2019 and subsequent model year vehicles, except for anti-lock brake system (ABS) control units or stability/traction control units, is field reprogrammable and has primary control over any rationality fault diagnostic or functional check for any input or output component required to be monitored by sections (e)(15) and (f)(15). For purposes of criteria (1) and (2) above, “primary control” over a monitor means the control unit does any of the following: (a) determines if any enable conditions are satisfied; (b) calculates all or part of the diagnostic decision statistic or metric by which pass or fail decisions are made (e.g., the comparison of a component’s measured or calculated level of performance to a fault threshold); or (c) makes or processes pass or fail decisions (e.g., debounces diagnostic decision statistics or commands MIL illumination or fault code storage). Further, for purposes of criterion (2)(a) above, all glow plugs in an engine shall be considered “one” component in lieu of each glow plug being considered a separate component. For purposes of criteria (1) and (2) above, “input component” and “output component” includes hybrid components required to be monitored in accordance with the requirements under section (e)(15.2.1), (e)(15.2.2), (f)(15.2.1), or (f)(15.2.2) “Smart device” refers to an electronic powertrain component or system that uses a microprocessor or microcontroller and does not meet the criteria to be classified as a “diagnostic or emission critical electronic powertrain control unit.” Devices that control transmissions or battery packs are excluded from this definition. Any component or system externally connected to the smart device shall not be considered part of the smart device unless: (1) It is a subcomponent integral to the function of the smart device; (2) It is permanently attached to the smart device with wires or one-time connectors; and (3) The smart device and subcomponent are designed, manufactured, installed, and serviced (per manufacturer published procedures) as a single component. ….OBD II system shall monitor for malfunction any electronic powertrain component/system not otherwise described in sections (e)(1) through (e)(14) that either provides input to (directly or indirectly) or receives commands from an on-board computer or smart device, and: (1) can affect emissions in excess of the criteria described in section (e)(15.1.2) during any reasonable in-use driving condition, or (2) is used as part of the diagnostic strategy for any other monitored system or component. Each input to or output from a smart device that meets criterion (1) or (2) above shall be monitored pursuant to section (e)(15). Further detection or pinpointing of faults internal to the smart device is not required. If the vehicle compensates or adjusts for deterioration or malfunction of the component/system, manufacturers are subject to the default action requirements of section (d)(2.2.3) or (e)(15.4.4) as applicable. (i) For computer encoded digital inputs: lack of communication from the input to the on-board computer shall be separately detected and store a separate fault code. Separate fault codes are not required for each distinct out-of-range fault. Based on the reg language above, the SAE J2012 committee plans to assign the following standard sets of DTCs for smart input devices: U06xx - Lost Communication With XXX Sensor P0XXX - XXX Sensor Circuit P0XXX - XXX Sensor Circuit Range/Performance P0XXX - XXX Sensor Circuit Low P0XXX - XXX Sensor Circuit High P0XXX - XXX Sensor Circuit Intermittent/Erratic SENT devices communicate sensor data (typically analog voltages) to the main microprocessor using serial data. The microprocessor in these devices also diagnoses sensor faults and communicates that information as well. This provides several advantages over conventional sensors: · Wiring faults can be identified differently from sensor faults in most cases. This helps a service technician identify the root cause of the fault and speeds up the repair. · Devices with multiple SENT sensors need only three wires (power, ground and signal) for all sensors on the device. This reduces weight and wiring complexity while increasing reliability. Sensor faults identified by the SENT device would use the traditional P-codes, e.g. circuit low, circuit high. Service technicians are already familiar wither these codes. SENT micro issues would set a Range/Performance code. These P-codes would indicate, with certainty, that the SENT device needs to be replaced. If communication is lost with the SENT device, the Lost Communication code would be set. Most likely, it means that there is a wiring issue even though it could also mean the SENT device failed and is no longer communicating with the main micro. The service technician would proceed to troubleshoot the wires, but if no wiring fault could be identified, the next action would be to replace the SENT device. Note that if there are three sensors, three Lost Communication codes would be set. Although not desirable, this strategy makes it unnecessary to come up with unique device names for every configuration of sensors and actuators that a manufacturer uses. SENT communication uses CRC errors to identify a communication fault. A CRC fault could be caused either by faulty wiring or by a faulty SENT microprocessor. CRC errors would also set the Lost Communication code. Similar to troubleshooting the Lost Communication code in the previous section, the service technician would proceed to troubleshoot the wires, but if no wiring fault could be identified, the next action would be to replace the SENT device. Although there was discussion of using an “Invalid Data Received from sensor XXX” code, there is no advantage in service as the repair procedure is the same – troubleshoot wires, then replace device. In addition, “Invalid Data“ codes are used to point the service technician to retrieve DTCs from another module. In this case, there is no module to retrieve codes from, so using this DTC would most likely cause confusion for service technicians. The SENT device will send in-range as well as out-of-range sensor values to the main micro. The main micro will use this data to trigger the circuit/out-of-range faults (XXX Sensor Circuit Low and XXX Sensor Circuit High DTCs) and XXX Sensor Circuit Range/Performance and XXX Sensor Circuit Intermittent/Erratic DTCs if applicable. These same values shall be output as J1979 PIDs (if applicable). Failed sensors will report out-of-range (not default) values as required by J1979. Diagnostic Validation testing will be accomplished by unplugging the SENT device and substituting a box that will produce SENT messages that simulate sensors with out of range values. This will test the main micro software’s ability to set the correct DTC for a given sensor fault. The SENT device supplier is responsible for ensuring that the sensor output value on SENT matches the transfer function specified for the sensor/device. The SAE J2012 committee plans to assign the following standard sets of DTCs for smart output devices: U06xx - Lost Communication With XXX actuator P0XXX XXX Actuator Control Circuit/Open P0XXX XXX Actuator Control Circuit Range/Performance P0XXX XXX Actuator Control Circuit Low P0XXX XXX Actuator Control Circuit High Smart actuator devices communicate via a two-way bus, usually CAN or LIN, with the main microprocessor using serial data. These devices may have one or more sensors (position, temperature, etc…) integrated also. The microprocessor in these devices also diagnoses actuator and sensor faults and communicates that information as well. Both actuator and sensor faults identified by the device would use the traditional P-codes, e.g. circuit low, circuit high, control circuit high, etc. Service technicians are already familiar wither these codes. Device micro issues would set a Range/Performance code. These P-codes would indicate that the entire device needs to be replaced. If communication is lost with the device, the Lost Communication code would be set. Most likely, it means that there is a wiring issue even though it could also mean the entire device failed and is no longer communicating with the main micro. The service technician would proceed to troubleshoot the wires, but if no wiring fault could be identified, the next action would be to replace the entire device. Note that if there are three sensors and an actuator, four Lost Communication codes would be set. Although not desirable, this strategy makes it unnecessary to come up with unique device names for every configuration of sensors and actuators that a manufacturer uses. The device will send actuator functional failure information. It will also send in-range as well as out-of-range sensor values to the main micro. The main micro will use this data to trigger the circuit/out-of-range faults (XXX Sensor Circuit Low and XXX Sensor Circuit High DTCs) and XXX Sensor Circuit Range/Performance and XXX Sensor Circuit Intermittent/Erratic DTCs if applicable. It will also use this information to trigger actuator control circuit faults (XXX Actuator Control Circuit/Open, XXX Actuator Control Circuit Low and XXX Actuator Control Circuit High DTCs) and XXX Actuator Range/Performance. These same values shall be output as J1979 PIDs (if applicable). Failed sensors will report out-of-range (not default) values as required by J1979. Diagnostic Validation testing will be accomplished by unplugging the smart device and substituting a box that will produce communication messages that simulate sensors with out of range values and actuator faults. This will test the main micro software’s ability to set the correct DTC for a given sensor fault. The smart device supplier is responsible for ensuring operational values on the communication bus matches the functionality specified for the device.
D3208: Drive Motor "A" Inverter Voltage Too High
D3209: Drive Motor "B" Inverter Voltage Too High

Sheet Smart Devices
A2: Smart Device
A3: The OBD-II regulations (1968.2) now address requirements for smart devices.
A4: “Diagnostic or emission critical” electronic powertrain control unit refers to the engine and transmission control unit(s). For the 2005 and subsequent model years, it also includes any other on-board electronic powertrain control unit that:
A5: (1) has primary control over any of the monitors required by sections (e)(1) through (e)(14), (e)(16), (f)(1) through (f)(14), and (f)(16), but does not include circuit or out-of-range fault monitors required by sections (e)(7.2.1)(B), (e)(7.2.2)(B), (e)(7.2.2)(D), (e)(7.2.3)(B), (e)(10.2.2)(A), (f)(5.2.1)(A)(ii), (f)(5.2.1)(B)(ii), (f)(5.2.2)(B), (f)(5.2.4)(B), and (f)(11.2.2)(A); or,
A6: (2) except for anti-lock brake system (ABS) control units or stability/traction control units, has primary control over any rationality fault diagnostics or functional check for more than four input components or more than two output components required to be monitored by sections (e)(15.0) and (f)(15); or
A7: (3) for 2019 and subsequent model year vehicles, except for anti-lock brake system (ABS) control units or stability/traction control units, is field reprogrammable and has primary control over any rationality fault diagnostic or functional check for any input or output component required to be monitored by sections (e)(15) and (f)(15).
A8: For purposes of criteria (1) and (2) above, “primary control” over a monitor means the control unit does any of the following: (a) determines if any enable conditions are satisfied; (b) calculates all or part of the diagnostic decision statistic or metric by which pass or fail decisions are made (e.g., the comparison of a component’s measured or calculated level of performance to a fault threshold); or (c) makes or processes pass or fail decisions (e.g., debounces diagnostic decision statistics or commands MIL illumination or fault code storage). Further, for purposes of criterion (2)(a) above, all glow plugs in an engine shall be considered “one” component in lieu of each glow plug being considered a separate component. For purposes of criteria (1) and (2) above, “input component” and “output component” includes hybrid components required to be monitored in accordance with the requirements under section (e)(15.2.1), (e)(15.2.2), (f)(15.2.1), or (f)(15.2.2)
A10: “Smart device” refers to an electronic powertrain component or system that uses a microprocessor or microcontroller and does not meet the criteria to be classified as a “diagnostic or emission critical electronic powertrain control unit.” Devices that control transmissions or battery packs are excluded from this definition. Any component or system externally connected to the smart device shall not be considered part of the smart device unless:
A11: (1) It is a subcomponent integral to the function of the smart device;
A12: (2) It is permanently attached to the smart device with wires or one-time connectors; and
A13: (3) The smart device and subcomponent are designed, manufactured, installed, and serviced (per manufacturer published procedures) as a single component.
A14: ….OBD II system shall monitor for malfunction any electronic powertrain component/system not otherwise described in sections (e)(1) through (e)(14) that either provides input to (directly or indirectly) or receives commands from an on-board computer or smart device, and: (1) can affect emissions in excess of the criteria described in section (e)(15.1.2) during any reasonable in-use driving condition, or (2) is used as part of the diagnostic strategy for any other monitored system or component. Each input to or output from a smart device that meets criterion (1) or (2) above shall be monitored pursuant to section (e)(15). Further detection or pinpointing of faults internal to the smart device is not required. If the vehicle compensates or adjusts for deterioration or malfunction of the component/system, manufacturers are subject to the default action requirements of section (d)(2.2.3) or (e)(15.4.4) as applicable.
... A64: Diagnostic Validation testing will be accomplished by unplugging the smart device and substituting a box that will produce communication messages that simulate sensors with out of range values and actuator faults. This will test the main micro software’s ability to set the correct DTC for a given sensor fault. The smart device supplier is responsible for ensuring operational values on the communication bus matches the functionality specified for the device.

Sheet FTB.Intro
A1: Terms and Definitions
A2: Introduction | B2: FTB is defined as the Failure Type Byte in extended DTCs most commonly used in CAN networks. The FTB is used with a base DTC made of two bytes designating the DTC number and B,C,P or U type. The base DTC will not specify a failure type such as an open or short circuit condition. Instead the failure type is specified by the FTB and is reported by an ECU with the base DTC. In effect then a reported DTC is made of the total of the three bytes. This standard leaves the choice of concatenating the information or separating the base DTC from the FTB open in regard to display for tools or information.
A3: DTC Failure Category and Sub Type definition | B3: The DTC Failure Type Byte defines the DTC Failure Category and Sub Type of a base DTC. It represents the type of fault in the circuit or system (e.g. sensor open circuit, sensor shorted to ground, algorithm based failure, etc).
A4: DTC Failure Type Byte parameter definition | B4: The DTC Failure Type consists of sixteen (16) different Failure Categories, where each category is associated with sixteen (16) Sub Type Failures (also known as symptoms). The Sub Type Failures are logically grouped in a DTC Failure Type Category. This shall simplify the selection of the appropriate Sub Type Failure {Symptom} for a DTC. The DTC Failure Category is coded in the High Nibble of the "DTC Failure Type Byte" and the Failure Sub Type is coded in the Low Nibble of the "DTC Failure Type Byte".
A5: DTC Selection | B5: The DTC annexes of SAE J2012 and ISO 15031-6 documents define many two byte DTCs with failure type information. If such a standard DTC is already defined for a component / system and that DTC description already comprehends the DTC Failure Type information, then the standard DTC number can be used and the DTC Failure Type Byte shall be set to a value of 00 hex. A DTC Failure Type Byte value of 00 hex indicates that no additional sub type information is contained in the DTC Failure Type Byte.
D3209: Drive Motor "A" Inverter Voltage Too High
D3210: Drive Motor "B" Inverter Voltage Too High

Sheet FTB.Examples
A1: The following examples show three (3) combinations of DTC and DTC Failure Type Byte, Format Identifiers 0x00 and 0x04.
A2: (012700 hex): P0127 Intake Air Temperature Too High | B2: An emissions related DTC which does not require any additional description included in the DTC Failure Type Byte (no DTC Failure Category name and no DTC Failure Sub Type, format 0x00)
A3: (803901 hex): B0039-01 Second Row Right Frontal Stage 1 Deployment Control - General Electrical Failure | B3: A DTC which requires an additional description included in the DTC Failure Type Byte (DTC Failure Category name and DTC Failure Sub Type $01, format 0x04)
A4: (403123 hex): C0031-23 Left Front Wheel Speed Sensor -General Signal Failure - Signal Stuck Low | B4: A DTC which requires an additional description included in the DTC Failure Type Byte (DTC Failure Category name and DTC Failure Sub Type $23, format 0x04)

Sheet FTB.Categories
A1: Failure Type Byte (hex) | B1: FTB Category | C1: FTB Category Description
A2: 00-0F | B2: General Failure Information | C2: This range includes all other categories and is used when the fault within that failure category is unique (not amenable to standardization through assignment of a new Sub Type) or when the detected fault is best described by two or more Sub Types within that Failure Category.
A3: 10-1F | B3: General Electrical Failures | C3: This range specifies the standard wiring failure modes (i.e., shorts and opens), and direct current (DC) quantities related by Ohm's Law.
A4: 20-2F | B4: General Signal Failures | C4: This range specifies quantities related to amplitude, frequency or rate of change, and wave shape.
A5: 30-3F | B5: FM (Frequency Modulation) / PWM (Pulse Width Modulation) Failures | C5: This range specifies faults related to Frequency Modulated (FM) and Pulse Width Modulated (PWM) inputs and outputs of the control module. This category also includes faults where position is determined by counts.
A6: 40-4F | B6: System Internal Failures | C6: This range specifies faults related to memory, software, and internal electrical circuitry; requiring component (control module, sensor, etc.) replacement.
A7: 50-5F | B7: System Programming Failures | C7: This range specifies faults related to operational software, calibrations, and options; remedied by configuring/programming a part of the system (control module, sensor, etc.).
A8: 60-6F | B8: Algorithm Based Failures | C8: This range specifies faults based on comparing two or more input parameters for plausibility, comparing a single parameter to itself with respect to time., or inhibits operation due to a reported failure of that circuit.
A9: 70-7F | B9: Mechanical Failures | C9: This range specifies faults detected by inappropriate motion in response to control module related input/controlled output.
A10: 80-8F | B10: Bus Signal Failures | C10: This range specifies faults related to bus hardware and signal integrity. This category is also used when the physical input for a signal is located in one control module and another control module diagnoses the circuit.
A11: 90-9F | B11: Component Failures | C11: This range specifies faults related to components connected to or monitored by a control module that do not themselves communicate to a scan tool via the data link connector. This range also specifies non-electrical faults related to components connected to or monitored by a control module.
A12: A0-AF | B12: General Electrical Failures - 2 | C12: This range specifies the standard wiring failure modes (i.e., shorts and opens), and direct current (DC) quantities related by Ohm's Law.
... A17: F0-FF | B17: Vehicle Manufacturer / System Supplier Specific | C17: This range is reserved for vehicle manufacturer/system supplier use.
D3208: Drive Motor "A" Inverter Voltage Too High
D3209: Drive Motor "B" Inverter Voltage Too High

Sheet FTB.Sub.Types
A1: Failure Type Byte (hex) | B1: DTC Sub Type Title | C1: DTC Sub Type Description
A2: 0 | B2: No Sub Type Information | C2: This sub type is used for failures where the base DTC text string provides the complete description of the failure itself (no Category and no Sub Type information used, e.g. emissions-related DTC (012700 hex): P0127 Intake Air Temperature Too High).
A3: 1 | B3: General Electrical Failure | C3: This sub type is used for General Electrical Failures that cannot be assigned to a specific sub type (Category information and no Sub Type information, e.g. DTC (803901): B0039-01 Second Row Right Frontal Stage 1 Deployment Control - General Electrical Failure).
A4: 2 | B4: General Signal Failure | C4: This sub type is used for General Signal Failures that cannot be assigned to a specific sub type (Category information and no Sub Type information, e.g. DTC (403002): C0030 Left Front Tone Wheel - General Signal Failure).
A5: 3 | B5: FM (Frequency Modulated) / PWM (Pulse Width Modulated) Failure | C5: This sub type is used for FM / PWM Failures that cannot be assigned to a specific sub type.
A6: 4 | B6: System Internal Failure | C6: This sub type is used for control module Internal Failures that cannot be assigned to a specific sub type.
A7: 5 | B7: System Programming Failure | C7: This sub type is used for System Programming Failures that cannot be assigned to a specific sub type.
A8: 6 | B8: Algorithm Based Failure | C8: This sub type is used for Algorithm Based Failures that cannot be assigned to a specific sub type.
A9: 7 | B9: Mechanical Failure | C9: This sub type is used for Mechanical Failures that cannot be assigned to a specific sub type.
A10: 8 | B10: Bus Signal / Message Failure | C10: This sub type is used for Bus Signal / Message Failures that cannot be assigned to a specific sub type.
A11: 9 | B11: Component Failure | C11: This sub type is used for Component Failures that cannot be assigned to a specific sub type.
A12: 0A | B12: General Electrical Failures - 2 | C12: This range specifies the standard wiring failure modes (i.e., shorts and opens), and direct current (DC) quantities related by Ohm's Law.
A13: 0B | B13: ISO/SAE Reserved | C13: This value is reserved by the document for future expansion.
A14: 0C | B14: ISO/SAE Reserved | C14: This value is reserved by the document for future expansion.
A15: 0D | B15: ISO/SAE Reserved | C15: This value is reserved by the document for future expansion.
A16: 0E | B16: ISO/SAE Reserved | C16: This value is reserved by the document for future expansion.
A17: 0F | B17: ISO/SAE Reserved | C17: This value is reserved by the document for future expansion.
A18: 10 | B18: ISO/SAE Reserved | C18: This value is reserved by the document for future expansion.
A19: 11 | B19: Circuit Short To Ground | C19: This sub type is used for failures where the control module measures ground (battery negative) potential for greater than a specified time period or when some other value less than the low voltage limit DTC Sub Type is measured.
A20: 12 | B20: Circuit Short To Battery | C20: This sub type is used for failures, where the control module measures vehicle system (battery positive) potential for greater than a specified time period or when some other value higher than the high voltage limit DTC Sub Type is measured.
A21: 13 | B21: Circuit Open | C21: This sub type is used for failures, where the control module determines an open circuit via lack of bias voltage, low current flow, no change in the state of an input in response to an output, etc.
A22: 14 | B22: Circuit Short To Ground or Open | C22: This sub type is used for failures, where the condition detected by the control module is the same for either indicated failure mode.
A23: 15 | B23: Circuit Short To Battery or Open | C23: This sub type is used for failures, where the condition detected by the control module is the same for either indicated failure mode.
A24: 16 | B24: Circuit Voltage Below Threshold | C24: This sub type is used for failures, where the control module measures a voltage below a specified range.
A25: 17 | B25: Circuit Voltage Above Threshold | C25: This sub type is used for failures where, the control module measures a voltage above a specified range.
A26: 18 | B26: Circuit Current Below Threshold | C26: This sub type is used for failures, where the control module measures current flow below a specified range.
A27: 19 | B27: Circuit Current Above Threshold | C27: This sub type is used for failures, where the control module measures current flow above a specified range.
A28: 1A | B28: Circuit Resistance Below Threshold | C28: This sub type is used for failures, where the control module infers a circuit resistance below a specified range.
A29: 1B | B29: Circuit Resistance Above Threshold | C29: This sub type is used for failures, where the control module infers a circuit resistance above a specified range.
A30: 1C | B30: Circuit Voltage Out of Range | C30: This sub type is used for failures, where the control module measures a voltage outside the expected range but not identified as too high or too low.
A31: 1D | B31: Circuit Current Out of Range | C31: This sub type is used for failures, where the control module measures a current outside the expected range but not identified as too high or too low.
A32: 1E | B32: Circuit Resistance Out of Range | C32: This sub type is used for failures, where the control module measures a resistance outside the expected range but not identified as too high or too low.
A33: 1F | B33: Circuit Intermittent | C33: This sub type is used for failures, where the control module momentarily detects one of the conditions defined above, but not long enough to set a specific sub type.
A34: 20 | B34: ISO/SAE Reserved | C34: This value is reserved by the document for future expansion.
A35: 21 | B35: Signal Amplitude < Minimum | C35: This sub type is used for failures where the control module measures a signal voltage amplitude below a specified range (e.g., low gain).
A36: 22 | B36: Signal Amplitude > Maximum | C36: This sub type is used for failures where the control module measures a signal voltage amplitude above a specified range (e.g., gain too high).
A37: 23 | B37: Signal Stuck Low | C37: This sub type is used for failures where the control module measures a signal that remains low when transitions are expected.
A38: 24 | B38: Signal Stuck High | C38: This sub type is used for failures where the control module measures a signal that remains high when transitions are expected.
A39: 25 | B39: Signal Shape / Waveform Failure | C39: This sub type is used for failures where the shape of the signal (plot of the amplitude with respect to time) is not correct, e.g., improper circuit impedance.
A40: 26 | B40: Signal Rate of Change Below Threshold | C40: This sub type is used for failures where the signal transitions more slowly than the specified limit.
...
